<?xml version="1.0" ?>
<robot name="Parking_Barrier" xmlns:xacro="http://www.ros.org/wiki/xacro">

<xacro:include filename="$(find Parking_Barrier_description)/urdf/materials.xacro" />
<xacro:include filename="$(find Parking_Barrier_description)/urdf/Parking_Barrier.trans" />
<xacro:include filename="$(find Parking_Barrier_description)/urdf/Parking_Barrier.gazebo" />
<link name="base_link">
  <inertial>
    <origin rpy="0 0 0" xyz="-0.015792478359560432 -0.0348550477581871 0.10476467691564022"/>
    <mass value="20.7066181110953"/>
    <inertia ixx="2.008589" ixy="0.00059" ixz="0.000278" iyy="2.042894" iyz="-0.147669" izz="0.580291"/>
  </inertial>
  <visual>
    <origin rpy="0 0 0" xyz="0 0 0"/>
    <geometry>
      <mesh filename="package://Parking_Barrier_description/meshes/base_link.stl" scale="0.001 0.001 0.001"/>
    </geometry>
    <material name="silver"/>
  </visual>
  <collision>
    <origin rpy="0 0 0" xyz="0 0 0"/>
    <geometry>
      <mesh filename="package://Parking_Barrier_description/meshes/base_link.stl" scale="0.001 0.001 0.001"/>
    </geometry>
  </collision>
</link>

<link name="barrier_1">
  <inertial>
    <origin rpy="0 0 0" xyz="1.3077866189318545 0.085480447707065 -0.007595444557914832"/>
    <mass value="62.329658342127686"/>
    <inertia ixx="0.043257" ixy="-0.096403" ixz="0.010631" iyy="49.255651" iyz="-0.00236" izz="49.228778"/>
  </inertial>
  <visual>
    <origin rpy="0 0 0" xyz="0.016028 -0.145074 -0.425841"/>
    <geometry>
      <mesh filename="package://Parking_Barrier_description/meshes/barrier_1.stl" scale="0.001 0.001 0.001"/>
    </geometry>
    <material name="silver"/>
  </visual>
  <collision>
    <origin rpy="0 0 0" xyz="0.016028 -0.145074 -0.425841"/>
    <geometry>
      <mesh filename="package://Parking_Barrier_description/meshes/barrier_1.stl" scale="0.001 0.001 0.001"/>
    </geometry>
  </collision>
</link>

<joint name="Rev1" type="revolute">
  <origin rpy="0 0 0" xyz="-0.016028 0.145074 0.425841"/>
  <parent link="base_link"/>
  <child link="barrier_1"/>
  <axis xyz="0.0 0.996195 -0.087156"/>
  <limit effort="100" lower="-1.570796" upper="0.0" velocity="100"/>
</joint>

</robot>
